from odoo import api, Command, fields, models, _
from odoo.exceptions import UserError


class PurchaseOrder(models.Model):
    _inherit = "purchase.order"

    payment_detail_ids = fields.One2many('payment.details', 'purchase_order_id',"Payment Details")
            
    @api.model
    def create(self, vals):
        res = super(PurchaseOrder, self).create(vals)
        if res.payment_term_id:
            payterm_vals = []
            if res.payment_detail_ids:
                for pay in res.payment_detail_ids:
                    pay.sudo().unlink()
            if res.message_follower_ids:
                for line in res.message_follower_ids:
                    line.sudo().unlink()
            for line in res.payment_term_id.line_ids:
                payterm_vals.append(Command.create({
                        'payment_term_id': res.payment_term_id.id,
                        'payment_term_line_id': line.id,
                    }))
            res.update({'payment_detail_ids': payterm_vals})
        return res
    
    def write(self, vals):
        result = super(PurchaseOrder, self).write(vals)
        res = self
        if res.message_follower_ids:
            for line in res.message_follower_ids:
                line.sudo().unlink()
        if 'payment_term_id' in vals:
            if res.payment_term_id:
                payterm_vals = []
                if res.payment_detail_ids:
                    for pay in res.payment_detail_ids:
                        pay.sudo().unlink()
                for line in res.payment_term_id.line_ids:
                    payterm_vals.append(Command.create({
                            'payment_term_id': res.payment_term_id.id,
                            'payment_term_line_id': line.id,
                        }))
                res.update({'payment_detail_ids': payterm_vals})
        return result
        
    
    
